<!doctype html>
<html>
<head>
	<meta charset="utf-8">
	<meta name="viewport" content="width=device-width,height=device-height,inital-scale=1.0,maximum-scale=1.0,user-scalable=no">
	<meta name="apple-mobile-web-app-capable" content="yes">
	<meta name="apple-mobile-web-app-status-bar-style" content="black">
	<meta name="format-detection" content="telephone=no">
	<title>throw_try_catch</title>
    <link type="text/css" rel="stylesheet" href="../../css/m/h_reset.css" />
    <link type="text/css" rel="stylesheet" href="../../css/m/h_global.css" />
	<script type="text/javascript" src="../../js/jquery-1.10.2.js"></script>
</head>
<body style="padding:20px;">


<xmp style=" font-family:微软雅黑; font-size:13px; line-height:24px;">
var array = null;
try {
    document.write(array[0]);
} catch(e) {
    document.writeln("Error name: " + e.name + "");
    document.writeln("Error message: " + e.message);
}
finally{
    alert("object is null");
}
------------------------------------------------------
--try里产生异常
--catch捕获异常e，执行catch内代码
--finally无论什么情况都会执行
------------------------------------------------------
--Error.name的六种值对应的信息：
1. EvalError：eval_r()的使用与定义不一致 
2. RangeError：数值越界 
3. ReferenceError：非法或不能识别的引用数值 
4. SyntaxError：发生语法解析错误 
5. TypeError：操作数类型错误 
6. URIError：URI处理函数使用不当

------------------------------------------------------



实例一：
----------------------
try{   
    print("Outer  try  running..");   
    try{   
       print("Nested  try  running...");   
       throw  "an  error";   
    }   
    catch(e){   
       print("Nested  catch  caught  "  +  e);   
       throw  e  +  "  re-thrown";   
    }   
    finally{   
       print("Nested  finally  is  running...");   
    }         
}   
catch(e){   
   print("Outer  catch  caught  "  +  e);   
}   
finally{   
   print("Outer  finally  running");   
}   
//Windows  Script  Host  作出该修改从而得出  WScript.Echo(s)   
function print(s){   
	document.write(s);   
} 
  
将得出以下结果：   
--------------
Outer    try    running..   
Nested    try    running...   
Nested    catch    caught    an    error   
Nested    finally    is    running...   
Outer    catch    caught    an    error    re-thrown   
Outer    finally    running

------------------------------------------------------


实例二：
----------------------

var x=prompt("Enter a number between 0 and 10:","")
try{ 
    if(x>10) 
    throw "Err1"
    else if(x<0)
    throw "Err2"
} 
catch(er){
    if(er=="Err1") 
    alert("Error! The value is too high")
    if(er == "Err2") 
    alert("Error! The value is too low") 
}
</xmp>

</body>
</html>
